[2025-05-20T18:10:40.631+0000] {taskinstance.py:1956} INFO - Dependencies all met for dep_context=non-requeueable deps ti=<TaskInstance: telegram_summary_channel_1283764331.summarize_daily_posts manual__2025-05-20T18:10:36.571372+00:00 [queued]>
[2025-05-20T18:10:40.640+0000] {taskinstance.py:1956} INFO - Dependencies all met for dep_context=requeueable deps ti=<TaskInstance: telegram_summary_channel_1283764331.summarize_daily_posts manual__2025-05-20T18:10:36.571372+00:00 [queued]>
[2025-05-20T18:10:40.640+0000] {taskinstance.py:2170} INFO - Starting attempt 1 of 2
[2025-05-20T18:10:40.654+0000] {taskinstance.py:2191} INFO - Executing <Task(DockerOperator): summarize_daily_posts> on 2025-05-20 18:10:36.571372+00:00
[2025-05-20T18:10:40.660+0000] {standard_task_runner.py:60} INFO - Started process 219 to run task
[2025-05-20T18:10:40.664+0000] {standard_task_runner.py:87} INFO - Running: ['airflow', 'tasks', 'run', 'telegram_summary_channel_1283764331', 'summarize_daily_posts', 'manual__2025-05-20T18:10:36.571372+00:00', '--job-id', '159', '--raw', '--subdir', 'DAGS_FOLDER/dag_generator.py', '--cfg-path', '/tmp/tmpetmo2si7']
[2025-05-20T18:10:40.666+0000] {standard_task_runner.py:88} INFO - Job 159: Subtask summarize_daily_posts
[2025-05-20T18:10:40.720+0000] {task_command.py:423} INFO - Running <TaskInstance: telegram_summary_channel_1283764331.summarize_daily_posts manual__2025-05-20T18:10:36.571372+00:00 [running]> on host 62cae552e501
[2025-05-20T18:10:40.839+0000] {taskinstance.py:2480} INFO - Exporting env vars: AIRFLOW_CTX_DAG_OWNER='airflow' AIRFLOW_CTX_DAG_ID='telegram_summary_channel_1283764331' AIRFLOW_CTX_TASK_ID='summarize_daily_posts' AIRFLOW_CTX_EXECUTION_DATE='2025-05-20T18:10:36.571372+00:00' AIRFLOW_CTX_TRY_NUMBER='1' AIRFLOW_CTX_DAG_RUN_ID='manual__2025-05-20T18:10:36.571372+00:00'
[2025-05-20T18:10:40.917+0000] {docker.py:359} INFO - Starting docker container from image telegram_summarizer_task:latest
[2025-05-20T18:10:41.506+0000] {docker.py:429} INFO - [2025-05-20 18:10:41] [INFO] [Summarizer] - Запуск основного процесса суммризатора (локальный или прямой вызов)...
[2025-05-20 18:10:41] [INFO] [Summarizer] - --- Запуск скрипта суммризации (Airflow Task) ---
[2025-05-20 18:10:41] [INFO] [Summarizer] - Попытка разбора XCom из переменной окружения 'XCOM_DATA_JSON'...
[2025-05-20T18:10:41.506+0000] {docker.py:429} INFO - [2025-05-20 18:10:41] [INFO] [Summarizer] - Прочитаны данные XCom: channel_id=1283764331, target_date_str=2025-05-20, parser_status=success_duplicates_found
[2025-05-20T18:10:41.507+0000] {docker.py:429} INFO - [2025-05-20 18:10:41] [WARNING] [Summarizer] - Статус предыдущей задачи парсинга: 'success_duplicates_found'. Саммаризация может быть неполной или основана на ошибочных данных.
[2025-05-20T18:10:41.517+0000] {docker.py:429} INFO - [2025-05-20 18:10:41] [INFO] [Summarizer] - Успешное подключение к БД parsing_results на postgres_results_db_service:5432
[2025-05-20 18:10:41] [INFO] [Summarizer] - Проверка/создание таблицы 'summaries'...
[2025-05-20T18:10:41.519+0000] {docker.py:429} INFO - [2025-05-20 18:10:41] [INFO] [Summarizer] - Таблица 'summaries' проверена/создана.
[2025-05-20T18:10:41.519+0000] {docker.py:429} INFO - [2025-05-20 18:10:41] [INFO] [Summarizer] - Извлечение постов для channel_id=1283764331 за дату=2025-05-20 (UTC: >= 2025-05-20 00:00:00+00:00 и < 2025-05-21 00:00:00+00:00)
[2025-05-20T18:10:41.521+0000] {docker.py:429} INFO - [2025-05-20 18:10:41] [INFO] [Summarizer] - Найдено 17 постов для саммаризации.
[2025-05-20T18:10:41.522+0000] {docker.py:429} INFO - [2025-05-20 18:10:41] [INFO] [Summarizer] - Формирование промпта из 17 текстов (макс. 15)...
[2025-05-20T18:10:41.522+0000] {docker.py:429} INFO - [2025-05-20 18:10:41] [WARNING] [Summarizer] - Достигнут лимит в 15 новостей для промпта. Остальные пропускаются.
[2025-05-20 18:10:41] [INFO] [Summarizer] - Промпт успешно сформирован из 15 новостей.
[2025-05-20 18:10:41] [INFO] [Summarizer] - Отправка запроса к GigaChat API...
[2025-05-20T18:10:41.691+0000] {docker.py:429} INFO - [2025-05-20 18:10:41] [INFO] [Summarizer] - HTTP Request: POST https://ngw.devices.sberbank.ru:9443/api/v2/oauth "HTTP/1.1 200 OK"
[2025-05-20T18:10:41.750+0000] {docker.py:429} INFO - [2025-05-20 18:10:41] [INFO] [Summarizer] - HTTP Request: POST https://gigachat.devices.sberbank.ru/api/v1/chat/completions "HTTP/1.1 429 Too Many Requests"
[2025-05-20 18:10:41] [ERROR] [Summarizer] - Ошибка при взаимодействии с GigaChat API: (URL('https://gigachat.devices.sberbank.ru/api/v1/chat/completions'), 429, b'{"status":429,"message":"Too Many Requests"}\n', Headers({'server': 'SynGX', 'date': 'Tue, 20 May 2025 18:10:41 GMT', 'content-type': 'application/json; charset=utf-8', 'content-length': '45', 'connection': 'keep-alive', 'x-request-id': '0a576090-c35c-4e30-ba09-f06974de1464', 'x-session-id': 'ffe02fd9-7ae0-4460-8f11-47c8e3e6fba9', 'allow': 'GET, POST', 'strict-transport-security': 'max-age=31536000; includeSubDomains'}))
Traceback (most recent call last):
  File "/app/summarizer.py", line 235, in get_summary_from_gigachat
    response = giga.chat(payload)
  File "/usr/local/lib/python3.9/site-packages/gigachat/client.py", line 316, in chat
    return self._decorator(lambda: post_chat.sync(self._client, chat=chat, access_token=self.token))
  File "/usr/local/lib/python3.9/site-packages/gigachat/client.py", line 260, in _decorator
    return call()
  File "/usr/local/lib/python3.9/site-packages/gigachat/client.py", line 316, in <lambda>
    return self._decorator(lambda: post_chat.sync(self._client, chat=chat, access_token=self.token))
  File "/usr/local/lib/python3.9/site-packages/gigachat/api/post_chat.py", line 34, in sync
    return build_response(response, ChatCompletion)
  File "/usr/local/lib/python3.9/site-packages/gigachat/api/utils.py", line 85, in build_response
    raise ResponseError(response.url, response.status_code, response.content, response.headers)
gigachat.exceptions.ResponseError: (URL('https://gigachat.devices.sberbank.ru/api/v1/chat/completions'), 429, b'{"status":429,"message":"Too Many Requests"}\n', Headers({'server': 'SynGX', 'date': 'Tue, 20 May 2025 18:10:41 GMT', 'content-type': 'application/json; charset=utf-8', 'content-length': '45', 'connection': 'keep-alive', 'x-request-id': '0a576090-c35c-4e30-ba09-f06974de1464', 'x-session-id': 'ffe02fd9-7ae0-4460-8f11-47c8e3e6fba9', 'allow': 'GET, POST', 'strict-transport-security': 'max-age=31536000; includeSubDomains'}))
[2025-05-20 18:10:41] [ERROR] [Summarizer] - Не удалось получить саммари от LLM. Саммари за день не будет обновлено/создано.
[2025-05-20 18:10:41] [INFO] [Summarizer] - Попытка сохранения/обновления саммари для channel_id=1283764331 за дату=2025-05-20
[2025-05-20T18:10:41.754+0000] {docker.py:429} INFO - [2025-05-20 18:10:41] [INFO] [Summarizer] - Саммари успешно сохранено/обновлено в БД.
[2025-05-20T18:10:41.754+0000] {docker.py:429} INFO - [2025-05-20 18:10:41] [INFO] [Summarizer] - Соединение с БД закрыто.
[2025-05-20 18:10:41] [INFO] [Summarizer] - --- Скрипт суммризации завершен с кодом выхода: 1 ---
[2025-05-20 18:10:41] [INFO] [Summarizer] - Суммризатор: Перехвачен SystemExit с кодом 1. Завершение.
[2025-05-20 18:10:41] [INFO] [Summarizer] - Скрипт суммризатора окончательно завершается с кодом 1 (из __main__ блока).
[2025-05-20T18:10:42.044+0000] {taskinstance.py:2698} ERROR - Task failed with exception
Traceback (most recent call last):
  File "/home/airflow/.local/lib/python3.8/site-packages/airflow/models/taskinstance.py", line 433, in _execute_task
    result = execute_callable(context=context, **execute_callable_kwargs)
  File "/home/airflow/.local/lib/python3.8/site-packages/airflow/providers/docker/operators/docker.py", line 502, in execute
    return self._run_image()
  File "/home/airflow/.local/lib/python3.8/site-packages/airflow/providers/docker/operators/docker.py", line 376, in _run_image
    return self._run_image_with_mounts(self.mounts, add_tmp_variable=False)
  File "/home/airflow/.local/lib/python3.8/site-packages/airflow/providers/docker/operators/docker.py", line 437, in _run_image_with_mounts
    raise DockerContainerFailedException(f"Docker container failed: {result!r}", logs=log_lines)
airflow.providers.docker.exceptions.DockerContainerFailedException: Docker container failed: {'StatusCode': 1}
[2025-05-20T18:10:42.049+0000] {taskinstance.py:1138} INFO - Marking task as UP_FOR_RETRY. dag_id=telegram_summary_channel_1283764331, task_id=summarize_daily_posts, execution_date=20250520T181036, start_date=20250520T181040, end_date=20250520T181042
[2025-05-20T18:10:42.068+0000] {standard_task_runner.py:107} ERROR - Failed to execute job 159 for task summarize_daily_posts (Docker container failed: {'StatusCode': 1}; 219)
[2025-05-20T18:10:42.082+0000] {local_task_job_runner.py:234} INFO - Task exited with return code 1
[2025-05-20T18:10:42.108+0000] {taskinstance.py:3280} INFO - 0 downstream tasks scheduled from follow-on schedule check
