[2025-05-18T21:29:56.059+0000] {taskinstance.py:1956} INFO - Dependencies all met for dep_context=non-requeueable deps ti=<TaskInstance: telegram_summary_channel_1137503644.summarize_daily_posts manual__2025-05-18T21:29:53.737322+00:00 [queued]>
[2025-05-18T21:29:56.063+0000] {taskinstance.py:1956} INFO - Dependencies all met for dep_context=requeueable deps ti=<TaskInstance: telegram_summary_channel_1137503644.summarize_daily_posts manual__2025-05-18T21:29:53.737322+00:00 [queued]>
[2025-05-18T21:29:56.063+0000] {taskinstance.py:2170} INFO - Starting attempt 1 of 2
[2025-05-18T21:29:56.068+0000] {taskinstance.py:2191} INFO - Executing <Task(DockerOperator): summarize_daily_posts> on 2025-05-18 21:29:53.737322+00:00
[2025-05-18T21:29:56.073+0000] {standard_task_runner.py:60} INFO - Started process 251 to run task
[2025-05-18T21:29:56.076+0000] {standard_task_runner.py:87} INFO - Running: ['airflow', 'tasks', 'run', 'telegram_summary_channel_1137503644', 'summarize_daily_posts', 'manual__2025-05-18T21:29:53.737322+00:00', '--job-id', '94', '--raw', '--subdir', 'DAGS_FOLDER/dag_generator.py', '--cfg-path', '/tmp/tmplnrxm322']
[2025-05-18T21:29:56.077+0000] {standard_task_runner.py:88} INFO - Job 94: Subtask summarize_daily_posts
[2025-05-18T21:29:56.105+0000] {task_command.py:423} INFO - Running <TaskInstance: telegram_summary_channel_1137503644.summarize_daily_posts manual__2025-05-18T21:29:53.737322+00:00 [running]> on host 91977f83f737
[2025-05-18T21:29:56.157+0000] {taskinstance.py:2480} INFO - Exporting env vars: AIRFLOW_CTX_DAG_OWNER='airflow' AIRFLOW_CTX_DAG_ID='telegram_summary_channel_1137503644' AIRFLOW_CTX_TASK_ID='summarize_daily_posts' AIRFLOW_CTX_EXECUTION_DATE='2025-05-18T21:29:53.737322+00:00' AIRFLOW_CTX_TRY_NUMBER='1' AIRFLOW_CTX_DAG_RUN_ID='manual__2025-05-18T21:29:53.737322+00:00'
[2025-05-18T21:29:56.201+0000] {docker.py:359} INFO - Starting docker container from image telegram_summarizer_task:latest
[2025-05-18T21:29:56.498+0000] {docker.py:429} INFO - [2025-05-18 21:29:56] [INFO] [Summarizer] - Запуск основного процесса суммризатора (локальный или прямой вызов)...
[2025-05-18 21:29:56] [INFO] [Summarizer] - --- Запуск скрипта суммризации (Airflow Task) ---
[2025-05-18 21:29:56] [INFO] [Summarizer] - Попытка разбора XCom из переменной окружения 'XCOM_DATA_JSON'...
[2025-05-18 21:29:56] [INFO] [Summarizer] - Прочитаны данные XCom: channel_id=1137503644, target_date_str=2025-05-18, parser_status=success_duplicates_found
[2025-05-18 21:29:56] [WARNING] [Summarizer] - Статус предыдущей задачи парсинга: 'success_duplicates_found'. Саммаризация может быть неполной или основана на ошибочных данных.
[2025-05-18T21:29:56.505+0000] {docker.py:429} INFO - [2025-05-18 21:29:56] [INFO] [Summarizer] - Успешное подключение к БД parsing_results на postgres_results_db_service:5432
[2025-05-18 21:29:56] [INFO] [Summarizer] - Проверка/создание таблицы 'summaries'...
[2025-05-18T21:29:56.507+0000] {docker.py:429} INFO - [2025-05-18 21:29:56] [INFO] [Summarizer] - Таблица 'summaries' проверена/создана.
[2025-05-18 21:29:56] [INFO] [Summarizer] - Извлечение постов для channel_id=1137503644 за дату=2025-05-18 (UTC: >= 2025-05-18 00:00:00+00:00 и < 2025-05-19 00:00:00+00:00)
[2025-05-18T21:29:56.508+0000] {docker.py:429} INFO - [2025-05-18 21:29:56] [INFO] [Summarizer] - Найдено 2 постов для саммаризации.
[2025-05-18 21:29:56] [INFO] [Summarizer] - Формирование промпта из 2 текстов (макс. 15)...
[2025-05-18 21:29:56] [INFO] [Summarizer] - Промпт успешно сформирован из 2 новостей.
[2025-05-18T21:29:56.508+0000] {docker.py:429} INFO - [2025-05-18 21:29:56] [INFO] [Summarizer] - Отправка запроса к GigaChat API...
[2025-05-18T21:30:01.307+0000] {docker.py:429} INFO - [2025-05-18 21:30:01] [ERROR] [Summarizer] - Ошибка при взаимодействии с GigaChat API: TLS/SSL connection has been closed (EOF) (_ssl.c:1147)
Traceback (most recent call last):
  File "/usr/local/lib/python3.9/site-packages/httpx/_transports/default.py", line 101, in map_httpcore_exceptions
    yield
  File "/usr/local/lib/python3.9/site-packages/httpx/_transports/default.py", line 250, in handle_request
    resp = self._pool.handle_request(req)
  File "/usr/local/lib/python3.9/site-packages/httpcore/_sync/connection_pool.py", line 256, in handle_request
    raise exc from None
  File "/usr/local/lib/python3.9/site-packages/httpcore/_sync/connection_pool.py", line 236, in handle_request
    response = connection.handle_request(
  File "/usr/local/lib/python3.9/site-packages/httpcore/_sync/connection.py", line 101, in handle_request
    raise exc
  File "/usr/local/lib/python3.9/site-packages/httpcore/_sync/connection.py", line 78, in handle_request
    stream = self._connect(request)
  File "/usr/local/lib/python3.9/site-packages/httpcore/_sync/connection.py", line 156, in _connect
    stream = stream.start_tls(**kwargs)
  File "/usr/local/lib/python3.9/site-packages/httpcore/_backends/sync.py", line 170, in start_tls
    raise exc
  File "/usr/local/lib/python3.9/contextlib.py", line 137, in __exit__
    self.gen.throw(typ, value, traceback)
  File "/usr/local/lib/python3.9/site-packages/httpcore/_exceptions.py", line 14, in map_exceptions
    raise to_exc(exc) from exc
httpcore.ConnectError: TLS/SSL connection has been closed (EOF) (_ssl.c:1147)

The above exception was the direct cause of the following exception:

Traceback (most recent call last):
  File "/app/summarizer.py", line 235, in get_summary_from_gigachat
    response = giga.chat(payload)
  File "/usr/local/lib/python3.9/site-packages/gigachat/client.py", line 316, in chat
    return self._decorator(lambda: post_chat.sync(self._client, chat=chat, access_token=self.token))
  File "/usr/local/lib/python3.9/site-packages/gigachat/client.py", line 259, in _decorator
    self._update_token()
  File "/usr/local/lib/python3.9/site-packages/gigachat/client.py", line 230, in _update_token
    self._access_token = post_auth.sync(
  File "/usr/local/lib/python3.9/site-packages/gigachat/api/post_auth.py", line 41, in sync
    response = client.request(**kwargs)
  File "/usr/local/lib/python3.9/site-packages/httpx/_client.py", line 825, in request
    return self.send(request, auth=auth, follow_redirects=follow_redirects)
  File "/usr/local/lib/python3.9/site-packages/httpx/_client.py", line 914, in send
    response = self._send_handling_auth(
  File "/usr/local/lib/python3.9/site-packages/httpx/_client.py", line 942, in _send_handling_auth
    response = self._send_handling_redirects(
  File "/usr/local/lib/python3.9/site-packages/httpx/_client.py", line 979, in _send_handling_redirects
    response = self._send_single_request(request)
  File "/usr/local/lib/python3.9/site-packages/httpx/_client.py", line 1014, in _send_single_request
    response = transport.handle_request(request)
  File "/usr/local/lib/python3.9/site-packages/httpx/_transports/default.py", line 250, in handle_request
    resp = self._pool.handle_request(req)
  File "/usr/local/lib/python3.9/contextlib.py", line 137, in __exit__
    self.gen.throw(typ, value, traceback)
  File "/usr/local/lib/python3.9/site-packages/httpx/_transports/default.py", line 118, in map_httpcore_exceptions
    raise mapped_exc(message) from exc
httpx.ConnectError: TLS/SSL connection has been closed (EOF) (_ssl.c:1147)
[2025-05-18 21:30:01] [ERROR] [Summarizer] - Не удалось получить саммари от LLM. Саммари за день не будет обновлено/создано.
[2025-05-18 21:30:01] [INFO] [Summarizer] - Попытка сохранения/обновления саммари для channel_id=1137503644 за дату=2025-05-18
[2025-05-18T21:30:01.308+0000] {docker.py:429} INFO - [2025-05-18 21:30:01] [INFO] [Summarizer] - Саммари успешно сохранено/обновлено в БД.
[2025-05-18 21:30:01] [INFO] [Summarizer] - Соединение с БД закрыто.
[2025-05-18 21:30:01] [INFO] [Summarizer] - --- Скрипт суммризации завершен с кодом выхода: 1 ---
[2025-05-18 21:30:01] [INFO] [Summarizer] - Суммризатор: Перехвачен SystemExit с кодом 1. Завершение.
[2025-05-18 21:30:01] [INFO] [Summarizer] - Скрипт суммризатора окончательно завершается с кодом 1 (из __main__ блока).
[2025-05-18T21:30:01.575+0000] {taskinstance.py:2698} ERROR - Task failed with exception
Traceback (most recent call last):
  File "/home/airflow/.local/lib/python3.8/site-packages/airflow/models/taskinstance.py", line 433, in _execute_task
    result = execute_callable(context=context, **execute_callable_kwargs)
  File "/home/airflow/.local/lib/python3.8/site-packages/airflow/providers/docker/operators/docker.py", line 502, in execute
    return self._run_image()
  File "/home/airflow/.local/lib/python3.8/site-packages/airflow/providers/docker/operators/docker.py", line 376, in _run_image
    return self._run_image_with_mounts(self.mounts, add_tmp_variable=False)
  File "/home/airflow/.local/lib/python3.8/site-packages/airflow/providers/docker/operators/docker.py", line 437, in _run_image_with_mounts
    raise DockerContainerFailedException(f"Docker container failed: {result!r}", logs=log_lines)
airflow.providers.docker.exceptions.DockerContainerFailedException: Docker container failed: {'StatusCode': 1}
[2025-05-18T21:30:01.577+0000] {taskinstance.py:1138} INFO - Marking task as UP_FOR_RETRY. dag_id=telegram_summary_channel_1137503644, task_id=summarize_daily_posts, execution_date=20250518T212953, start_date=20250518T212956, end_date=20250518T213001
[2025-05-18T21:30:01.611+0000] {standard_task_runner.py:107} ERROR - Failed to execute job 94 for task summarize_daily_posts (Docker container failed: {'StatusCode': 1}; 251)
[2025-05-18T21:30:01.669+0000] {local_task_job_runner.py:234} INFO - Task exited with return code 1
[2025-05-18T21:30:01.689+0000] {taskinstance.py:3280} INFO - 0 downstream tasks scheduled from follow-on schedule check
