[2025-05-18T21:14:13.416+0000] {taskinstance.py:1956} INFO - Dependencies all met for dep_context=non-requeueable deps ti=<TaskInstance: telegram_summary_channel_1137503644.summarize_daily_posts manual__2025-05-18T21:11:06.233199+00:00 [queued]>
[2025-05-18T21:14:13.421+0000] {taskinstance.py:1956} INFO - Dependencies all met for dep_context=requeueable deps ti=<TaskInstance: telegram_summary_channel_1137503644.summarize_daily_posts manual__2025-05-18T21:11:06.233199+00:00 [queued]>
[2025-05-18T21:14:13.421+0000] {taskinstance.py:2170} INFO - Starting attempt 2 of 2
[2025-05-18T21:14:13.427+0000] {taskinstance.py:2191} INFO - Executing <Task(DockerOperator): summarize_daily_posts> on 2025-05-18 21:11:06.233199+00:00
[2025-05-18T21:14:13.433+0000] {standard_task_runner.py:60} INFO - Started process 259 to run task
[2025-05-18T21:14:13.436+0000] {standard_task_runner.py:87} INFO - Running: ['airflow', 'tasks', 'run', 'telegram_summary_channel_1137503644', 'summarize_daily_posts', 'manual__2025-05-18T21:11:06.233199+00:00', '--job-id', '77', '--raw', '--subdir', 'DAGS_FOLDER/dag_generator.py', '--cfg-path', '/tmp/tmp6v84gi7y']
[2025-05-18T21:14:13.438+0000] {standard_task_runner.py:88} INFO - Job 77: Subtask summarize_daily_posts
[2025-05-18T21:14:13.475+0000] {task_command.py:423} INFO - Running <TaskInstance: telegram_summary_channel_1137503644.summarize_daily_posts manual__2025-05-18T21:11:06.233199+00:00 [running]> on host e5cd1b16e7bb
[2025-05-18T21:14:13.538+0000] {taskinstance.py:2480} INFO - Exporting env vars: AIRFLOW_CTX_DAG_OWNER='airflow' AIRFLOW_CTX_DAG_ID='telegram_summary_channel_1137503644' AIRFLOW_CTX_TASK_ID='summarize_daily_posts' AIRFLOW_CTX_EXECUTION_DATE='2025-05-18T21:11:06.233199+00:00' AIRFLOW_CTX_TRY_NUMBER='2' AIRFLOW_CTX_DAG_RUN_ID='manual__2025-05-18T21:11:06.233199+00:00'
[2025-05-18T21:14:13.594+0000] {docker.py:359} INFO - Starting docker container from image telegram_summarizer_task:latest
[2025-05-18T21:14:13.942+0000] {docker.py:429} INFO - [2025-05-18 21:14:13] [INFO] [Summarizer] - Запуск основного процесса суммризатора (локальный или прямой вызов)...
[2025-05-18 21:14:13] [INFO] [Summarizer] - --- Запуск скрипта суммризации (Airflow Task) ---
[2025-05-18 21:14:13] [INFO] [Summarizer] - Попытка разбора XCom из переменной окружения 'XCOM_DATA_JSON'...
[2025-05-18 21:14:13] [INFO] [Summarizer] - Прочитаны данные XCom: channel_id=1137503644, target_date_str=2025-05-18, parser_status=success_duplicates_found
[2025-05-18 21:14:13] [WARNING] [Summarizer] - Статус предыдущей задачи парсинга: 'success_duplicates_found'. Саммаризация может быть неполной или основана на ошибочных данных.
[2025-05-18T21:14:13.954+0000] {docker.py:429} INFO - [2025-05-18 21:14:13] [INFO] [Summarizer] - Успешное подключение к БД parsing_results на postgres_results_db_service:5432
[2025-05-18 21:14:13] [INFO] [Summarizer] - Проверка/создание таблицы 'summaries'...
[2025-05-18T21:14:13.956+0000] {docker.py:429} INFO - [2025-05-18 21:14:13] [ERROR] [Summarizer] - Ошибка при настройке таблицы 'summaries': column "channel_id" does not exist
Traceback (most recent call last):
  File "/app/summarizer.py", line 98, in setup_summaries_table
    cur.execute("""
psycopg2.errors.UndefinedColumn: column "channel_id" does not exist
[2025-05-18T21:14:13.959+0000] {docker.py:429} INFO - [2025-05-18 21:14:13] [WARNING] [Summarizer] - Скрипт суммризации завершается через sys.exit() с кодом: 1
[2025-05-18 21:14:13] [INFO] [Summarizer] - Соединение с БД закрыто.
[2025-05-18 21:14:13] [INFO] [Summarizer] - --- Скрипт суммризации завершен с кодом выхода: 1 ---
[2025-05-18 21:14:13] [INFO] [Summarizer] - Суммризатор: Перехвачен SystemExit с кодом 1. Завершение.
[2025-05-18 21:14:13] [INFO] [Summarizer] - Скрипт суммризатора окончательно завершается с кодом 1 (из __main__ блока).
[2025-05-18T21:14:14.127+0000] {taskinstance.py:2698} ERROR - Task failed with exception
Traceback (most recent call last):
  File "/home/airflow/.local/lib/python3.8/site-packages/airflow/models/taskinstance.py", line 433, in _execute_task
    result = execute_callable(context=context, **execute_callable_kwargs)
  File "/home/airflow/.local/lib/python3.8/site-packages/airflow/providers/docker/operators/docker.py", line 502, in execute
    return self._run_image()
  File "/home/airflow/.local/lib/python3.8/site-packages/airflow/providers/docker/operators/docker.py", line 376, in _run_image
    return self._run_image_with_mounts(self.mounts, add_tmp_variable=False)
  File "/home/airflow/.local/lib/python3.8/site-packages/airflow/providers/docker/operators/docker.py", line 437, in _run_image_with_mounts
    raise DockerContainerFailedException(f"Docker container failed: {result!r}", logs=log_lines)
airflow.providers.docker.exceptions.DockerContainerFailedException: Docker container failed: {'StatusCode': 1}
[2025-05-18T21:14:14.129+0000] {taskinstance.py:1138} INFO - Marking task as FAILED. dag_id=telegram_summary_channel_1137503644, task_id=summarize_daily_posts, execution_date=20250518T211106, start_date=20250518T211413, end_date=20250518T211414
[2025-05-18T21:14:14.139+0000] {standard_task_runner.py:107} ERROR - Failed to execute job 77 for task summarize_daily_posts (Docker container failed: {'StatusCode': 1}; 259)
[2025-05-18T21:14:14.171+0000] {local_task_job_runner.py:234} INFO - Task exited with return code 1
[2025-05-18T21:14:14.183+0000] {taskinstance.py:3280} INFO - 0 downstream tasks scheduled from follow-on schedule check
