[2025-05-20T22:00:01.123+0000] {taskinstance.py:1956} INFO - Dependencies all met for dep_context=non-requeueable deps ti=<TaskInstance: telegram_summary_channel_1137503644.parse_channel_posts scheduled__2025-05-20T21:30:00+00:00 [queued]>
[2025-05-20T22:00:01.130+0000] {taskinstance.py:1956} INFO - Dependencies all met for dep_context=requeueable deps ti=<TaskInstance: telegram_summary_channel_1137503644.parse_channel_posts scheduled__2025-05-20T21:30:00+00:00 [queued]>
[2025-05-20T22:00:01.130+0000] {taskinstance.py:2170} INFO - Starting attempt 1 of 2
[2025-05-20T22:00:01.144+0000] {taskinstance.py:2191} INFO - Executing <Task(DockerOperator): parse_channel_posts> on 2025-05-20 21:30:00+00:00
[2025-05-20T22:00:01.151+0000] {standard_task_runner.py:60} INFO - Started process 1606 to run task
[2025-05-20T22:00:01.157+0000] {standard_task_runner.py:87} INFO - Running: ['airflow', 'tasks', 'run', 'telegram_summary_channel_1137503644', 'parse_channel_posts', 'scheduled__2025-05-20T21:30:00+00:00', '--job-id', '189', '--raw', '--subdir', 'DAGS_FOLDER/dag_generator.py', '--cfg-path', '/tmp/tmpxx3ju5dk']
[2025-05-20T22:00:01.162+0000] {standard_task_runner.py:88} INFO - Job 189: Subtask parse_channel_posts
[2025-05-20T22:00:01.228+0000] {task_command.py:423} INFO - Running <TaskInstance: telegram_summary_channel_1137503644.parse_channel_posts scheduled__2025-05-20T21:30:00+00:00 [running]> on host 56d55b2fde31
[2025-05-20T22:00:01.341+0000] {taskinstance.py:2480} INFO - Exporting env vars: AIRFLOW_CTX_DAG_OWNER='airflow' AIRFLOW_CTX_DAG_ID='telegram_summary_channel_1137503644' AIRFLOW_CTX_TASK_ID='parse_channel_posts' AIRFLOW_CTX_EXECUTION_DATE='2025-05-20T21:30:00+00:00' AIRFLOW_CTX_TRY_NUMBER='1' AIRFLOW_CTX_DAG_RUN_ID='scheduled__2025-05-20T21:30:00+00:00'
[2025-05-20T22:00:01.443+0000] {docker.py:359} INFO - Starting docker container from image telegram_parser_task:latest
[2025-05-20T22:00:02.458+0000] {docker.py:429} INFO - [2025-05-20 22:00:02] [INFO] [Parser] - Запуск основного асинхронного процесса парсера (локальный или прямой вызов)...
[2025-05-20T22:00:02.459+0000] {docker.py:429} INFO - [2025-05-20 22:00:02] [INFO] [Parser] - --- Запуск скрипта парсера (Airflow Task) ---
[2025-05-20 22:00:02] [INFO] [Parser] - Попытка подключения к БД (1/5): host=postgres_results_db_service port=5432 dbname=parsing_results user=parser_user
[2025-05-20T22:00:02.466+0000] {docker.py:429} INFO - [2025-05-20 22:00:02] [INFO] [Parser] - Успешное подключение к БД!
[2025-05-20 22:00:02] [INFO] [Parser] - Проверка/создание таблицы 'telegram_messages'...
[2025-05-20T22:00:02.475+0000] {docker.py:429} INFO - [2025-05-20 22:00:02] [INFO] [Parser] - Схема БД 'telegram_messages' проверена/обновлена.
[2025-05-20 22:00:02] [INFO] [Parser] - Инициализация Telegram клиента с сессией: /app/session/my_telegram_session
[2025-05-20 22:00:02] [INFO] [Parser] - Файл сессии '/app/session/my_telegram_session.session' существует: True
[2025-05-20T22:00:02.476+0000] {docker.py:429} INFO - [2025-05-20 22:00:02] [INFO] [Parser] - Подключение к Telegram...
[2025-05-20T22:00:02.477+0000] {docker.py:429} INFO - [2025-05-20 22:00:02] [INFO] [Parser] - Connecting to 149.154.167.51:443/TcpFull...
[2025-05-20T22:00:02.836+0000] {docker.py:429} INFO - [2025-05-20 22:00:02] [INFO] [Parser] - Connection to 149.154.167.51:443/TcpFull complete!
[2025-05-20T22:00:08.782+0000] {docker.py:429} INFO - [2025-05-20 22:00:08] [ERROR] [Parser] - Непредвиденная ошибка при инициализации Telegram клиента: database is locked
Traceback (most recent call last):
  File "/app/telegram_parser.py", line 157, in initialize_telegram_client
    await telegram_client.connect()
  File "/usr/local/lib/python3.9/site-packages/telethon/client/telegrambaseclient.py", line 601, in connect
    me = await self.get_me()
  File "/usr/local/lib/python3.9/site-packages/telethon/client/users.py", line 170, in get_me
    me = (await self(
  File "/usr/local/lib/python3.9/site-packages/telethon/client/users.py", line 30, in __call__
    return await self._call(self._sender, request, ordered=ordered)
  File "/usr/local/lib/python3.9/site-packages/telethon/client/users.py", line 93, in _call
    self.session.process_entities(result)
  File "/usr/local/lib/python3.9/site-packages/telethon/sessions/sqlite.py", line 301, in process_entities
    c.executemany(
sqlite3.OperationalError: database is locked
[2025-05-20 22:00:08] [INFO] [Parser] - Disconnecting from 149.154.167.51:443/TcpFull...
[2025-05-20 22:00:08] [INFO] [Parser] - Disconnection from 149.154.167.51:443/TcpFull complete!
[2025-05-20T22:00:10.623+0000] {docker.py:429} INFO - [2025-05-20 22:00:10] [ERROR] [Parser] - Критическая ошибка в main: Не удалось инициализировать или подключиться к Telegram.
Traceback (most recent call last):
  File "/app/telegram_parser.py", line 343, in main
    raise Exception("Не удалось инициализировать или подключиться к Telegram.")
Exception: Не удалось инициализировать или подключиться к Telegram.
[2025-05-20 22:00:10] [INFO] [Parser] - Запись данных XCom в файл: /airflow/xcom/return.json
[2025-05-20T22:00:10.624+0000] {docker.py:429} INFO - [2025-05-20 22:00:10] [INFO] [Parser] - Создана директория для XCom: /airflow/xcom
[2025-05-20T22:00:10.624+0000] {docker.py:429} INFO - [2025-05-20 22:00:10] [INFO] [Parser] - Данные XCom успешно записаны: {'channel_id': 1137503644, 'target_date_str': '2025-05-20', 'parsed_count': 0, 'saved_count': 0, 'skipped_because_duplicate_or_no_error': 0, 'status': 'failure', 'error_type': 'Exception', 'error_message': 'Не удалось инициализировать или подключиться к Telegram.'}
[2025-05-20 22:00:10] [INFO] [Parser] - Закрытие соединения с БД...
[2025-05-20T22:00:10.628+0000] {docker.py:429} INFO - [2025-05-20 22:00:10] [INFO] [Parser] - Соединение с БД закрыто.
[2025-05-20 22:00:10] [INFO] [Parser] - --- Скрипт парсера завершен с кодом выхода: 1 (XCom записан: True) ---
[2025-05-20 22:00:10] [INFO] [Parser] - Перехвачен SystemExit с кодом 1. Завершение (из __main__).
[2025-05-20T22:00:10.704+0000] {docker.py:429} INFO - Python script exited with code 0
Found XCom file, outputting its content for XCom push:
[2025-05-20T22:00:10.706+0000] {docker.py:429} INFO - {
  "channel_id": 1137503644,
  "target_date_str": "2025-05-20",
  "parsed_count": 0,
  "saved_count": 0,
  "skipped_because_duplicate_or_no_error": 0,
  "status": "failure",
  "error_type": "Exception",
  "error_message": "Не удалось инициализировать или подключиться к Telegram."
}
[2025-05-20T22:00:11.075+0000] {taskinstance.py:1138} INFO - Marking task as SUCCESS. dag_id=telegram_summary_channel_1137503644, task_id=parse_channel_posts, execution_date=20250520T213000, start_date=20250520T220001, end_date=20250520T220011
[2025-05-20T22:00:11.139+0000] {local_task_job_runner.py:234} INFO - Task exited with return code 0
[2025-05-20T22:00:11.165+0000] {taskinstance.py:3280} INFO - 1 downstream tasks scheduled from follow-on schedule check
