[2025-05-20T17:57:09.387+0000] {taskinstance.py:1956} INFO - Dependencies all met for dep_context=non-requeueable deps ti=<TaskInstance: telegram_summary_channel_1598472442.summarize_daily_posts scheduled__2025-05-19T10:30:00+00:00 [queued]>
[2025-05-20T17:57:09.396+0000] {taskinstance.py:1956} INFO - Dependencies all met for dep_context=requeueable deps ti=<TaskInstance: telegram_summary_channel_1598472442.summarize_daily_posts scheduled__2025-05-19T10:30:00+00:00 [queued]>
[2025-05-20T17:57:09.397+0000] {taskinstance.py:2170} INFO - Starting attempt 2 of 2
[2025-05-20T17:57:09.412+0000] {taskinstance.py:2191} INFO - Executing <Task(DockerOperator): summarize_daily_posts> on 2025-05-19 10:30:00+00:00
[2025-05-20T17:57:09.421+0000] {standard_task_runner.py:60} INFO - Started process 371 to run task
[2025-05-20T17:57:09.428+0000] {standard_task_runner.py:87} INFO - Running: ['airflow', 'tasks', 'run', 'telegram_summary_channel_1598472442', 'summarize_daily_posts', 'scheduled__2025-05-19T10:30:00+00:00', '--job-id', '140', '--raw', '--subdir', 'DAGS_FOLDER/dag_generator.py', '--cfg-path', '/tmp/tmpya8dw6us']
[2025-05-20T17:57:09.432+0000] {standard_task_runner.py:88} INFO - Job 140: Subtask summarize_daily_posts
[2025-05-20T17:57:09.518+0000] {task_command.py:423} INFO - Running <TaskInstance: telegram_summary_channel_1598472442.summarize_daily_posts scheduled__2025-05-19T10:30:00+00:00 [running]> on host dc14f5f0ef5f
[2025-05-20T17:57:09.691+0000] {taskinstance.py:2480} INFO - Exporting env vars: AIRFLOW_CTX_DAG_OWNER='airflow' AIRFLOW_CTX_DAG_ID='telegram_summary_channel_1598472442' AIRFLOW_CTX_TASK_ID='summarize_daily_posts' AIRFLOW_CTX_EXECUTION_DATE='2025-05-19T10:30:00+00:00' AIRFLOW_CTX_TRY_NUMBER='2' AIRFLOW_CTX_DAG_RUN_ID='scheduled__2025-05-19T10:30:00+00:00'
[2025-05-20T17:57:09.836+0000] {docker.py:359} INFO - Starting docker container from image telegram_summarizer_task:latest
[2025-05-20T17:57:10.411+0000] {docker.py:429} INFO - [2025-05-20 17:57:10] [INFO] [Summarizer] - Запуск основного процесса суммризатора (локальный или прямой вызов)...
[2025-05-20 17:57:10] [INFO] [Summarizer] - --- Запуск скрипта суммризации (Airflow Task) ---
[2025-05-20 17:57:10] [INFO] [Summarizer] - Попытка разбора XCom из переменной окружения 'XCOM_DATA_JSON'...
[2025-05-20 17:57:10] [INFO] [Summarizer] - Прочитаны данные XCom: channel_id=1598472442, target_date_str=2025-05-19, parser_status=success
[2025-05-20T17:57:10.425+0000] {docker.py:429} INFO - [2025-05-20 17:57:10] [INFO] [Summarizer] - Успешное подключение к БД parsing_results на postgres_results_db_service:5432
[2025-05-20 17:57:10] [INFO] [Summarizer] - Проверка/создание таблицы 'summaries'...
[2025-05-20T17:57:10.427+0000] {docker.py:429} INFO - [2025-05-20 17:57:10] [INFO] [Summarizer] - Таблица 'summaries' проверена/создана.
[2025-05-20 17:57:10] [INFO] [Summarizer] - Извлечение постов для channel_id=1598472442 за дату=2025-05-19 (UTC: >= 2025-05-19 00:00:00+00:00 и < 2025-05-20 00:00:00+00:00)
[2025-05-20T17:57:10.429+0000] {docker.py:429} INFO - [2025-05-20 17:57:10] [INFO] [Summarizer] - Найдено 1 постов для саммаризации.
[2025-05-20 17:57:10] [INFO] [Summarizer] - Формирование промпта из 1 текстов (макс. 15)...
[2025-05-20 17:57:10] [INFO] [Summarizer] - Промпт успешно сформирован из 1 новостей.
[2025-05-20 17:57:10] [INFO] [Summarizer] - Отправка запроса к GigaChat API...
[2025-05-20T17:57:10.542+0000] {docker.py:429} INFO - [2025-05-20 17:57:10] [INFO] [Summarizer] - HTTP Request: POST https://ngw.devices.sberbank.ru:9443/api/v2/oauth "HTTP/1.1 200 OK"
[2025-05-20T17:57:15.353+0000] {docker.py:429} INFO - [2025-05-20 17:57:15] [ERROR] [Summarizer] - Ошибка при взаимодействии с GigaChat API: TLS/SSL connection has been closed (EOF) (_ssl.c:1147)
Traceback (most recent call last):
  File "/usr/local/lib/python3.9/site-packages/httpx/_transports/default.py", line 101, in map_httpcore_exceptions
    yield
  File "/usr/local/lib/python3.9/site-packages/httpx/_transports/default.py", line 250, in handle_request
    resp = self._pool.handle_request(req)
  File "/usr/local/lib/python3.9/site-packages/httpcore/_sync/connection_pool.py", line 256, in handle_request
    raise exc from None
  File "/usr/local/lib/python3.9/site-packages/httpcore/_sync/connection_pool.py", line 236, in handle_request
    response = connection.handle_request(
  File "/usr/local/lib/python3.9/site-packages/httpcore/_sync/connection.py", line 101, in handle_request
    raise exc
  File "/usr/local/lib/python3.9/site-packages/httpcore/_sync/connection.py", line 78, in handle_request
    stream = self._connect(request)
  File "/usr/local/lib/python3.9/site-packages/httpcore/_sync/connection.py", line 156, in _connect
    stream = stream.start_tls(**kwargs)
  File "/usr/local/lib/python3.9/site-packages/httpcore/_backends/sync.py", line 170, in start_tls
    raise exc
  File "/usr/local/lib/python3.9/contextlib.py", line 137, in __exit__
    self.gen.throw(typ, value, traceback)
  File "/usr/local/lib/python3.9/site-packages/httpcore/_exceptions.py", line 14, in map_exceptions
    raise to_exc(exc) from exc
httpcore.ConnectError: TLS/SSL connection has been closed (EOF) (_ssl.c:1147)

The above exception was the direct cause of the following exception:

Traceback (most recent call last):
  File "/app/summarizer.py", line 235, in get_summary_from_gigachat
    response = giga.chat(payload)
  File "/usr/local/lib/python3.9/site-packages/gigachat/client.py", line 316, in chat
    return self._decorator(lambda: post_chat.sync(self._client, chat=chat, access_token=self.token))
  File "/usr/local/lib/python3.9/site-packages/gigachat/client.py", line 260, in _decorator
    return call()
  File "/usr/local/lib/python3.9/site-packages/gigachat/client.py", line 316, in <lambda>
    return self._decorator(lambda: post_chat.sync(self._client, chat=chat, access_token=self.token))
  File "/usr/local/lib/python3.9/site-packages/gigachat/api/post_chat.py", line 33, in sync
    response = client.request(**kwargs)
  File "/usr/local/lib/python3.9/site-packages/httpx/_client.py", line 825, in request
    return self.send(request, auth=auth, follow_redirects=follow_redirects)
  File "/usr/local/lib/python3.9/site-packages/httpx/_client.py", line 914, in send
    response = self._send_handling_auth(
  File "/usr/local/lib/python3.9/site-packages/httpx/_client.py", line 942, in _send_handling_auth
    response = self._send_handling_redirects(
  File "/usr/local/lib/python3.9/site-packages/httpx/_client.py", line 979, in _send_handling_redirects
    response = self._send_single_request(request)
  File "/usr/local/lib/python3.9/site-packages/httpx/_client.py", line 1014, in _send_single_request
    response = transport.handle_request(request)
  File "/usr/local/lib/python3.9/site-packages/httpx/_transports/default.py", line 250, in handle_request
    resp = self._pool.handle_request(req)
  File "/usr/local/lib/python3.9/contextlib.py", line 137, in __exit__
    self.gen.throw(typ, value, traceback)
  File "/usr/local/lib/python3.9/site-packages/httpx/_transports/default.py", line 118, in map_httpcore_exceptions
    raise mapped_exc(message) from exc
httpx.ConnectError: TLS/SSL connection has been closed (EOF) (_ssl.c:1147)
[2025-05-20 17:57:15] [ERROR] [Summarizer] - Не удалось получить саммари от LLM. Саммари за день не будет обновлено/создано.
[2025-05-20 17:57:15] [INFO] [Summarizer] - Попытка сохранения/обновления саммари для channel_id=1598472442 за дату=2025-05-19
[2025-05-20T17:57:15.357+0000] {docker.py:429} INFO - [2025-05-20 17:57:15] [INFO] [Summarizer] - Саммари успешно сохранено/обновлено в БД.
[2025-05-20 17:57:15] [INFO] [Summarizer] - Соединение с БД закрыто.
[2025-05-20 17:57:15] [INFO] [Summarizer] - --- Скрипт суммризации завершен с кодом выхода: 1 ---
[2025-05-20 17:57:15] [INFO] [Summarizer] - Суммризатор: Перехвачен SystemExit с кодом 1. Завершение.
[2025-05-20 17:57:15] [INFO] [Summarizer] - Скрипт суммризатора окончательно завершается с кодом 1 (из __main__ блока).
[2025-05-20T17:57:15.724+0000] {taskinstance.py:2698} ERROR - Task failed with exception
Traceback (most recent call last):
  File "/home/airflow/.local/lib/python3.8/site-packages/airflow/models/taskinstance.py", line 433, in _execute_task
    result = execute_callable(context=context, **execute_callable_kwargs)
  File "/home/airflow/.local/lib/python3.8/site-packages/airflow/providers/docker/operators/docker.py", line 502, in execute
    return self._run_image()
  File "/home/airflow/.local/lib/python3.8/site-packages/airflow/providers/docker/operators/docker.py", line 376, in _run_image
    return self._run_image_with_mounts(self.mounts, add_tmp_variable=False)
  File "/home/airflow/.local/lib/python3.8/site-packages/airflow/providers/docker/operators/docker.py", line 437, in _run_image_with_mounts
    raise DockerContainerFailedException(f"Docker container failed: {result!r}", logs=log_lines)
airflow.providers.docker.exceptions.DockerContainerFailedException: Docker container failed: {'StatusCode': 1}
[2025-05-20T17:57:15.727+0000] {taskinstance.py:1138} INFO - Marking task as FAILED. dag_id=telegram_summary_channel_1598472442, task_id=summarize_daily_posts, execution_date=20250519T103000, start_date=20250520T175709, end_date=20250520T175715
[2025-05-20T17:57:15.749+0000] {standard_task_runner.py:107} ERROR - Failed to execute job 140 for task summarize_daily_posts (Docker container failed: {'StatusCode': 1}; 371)
[2025-05-20T17:57:15.774+0000] {local_task_job_runner.py:234} INFO - Task exited with return code 1
[2025-05-20T17:57:15.795+0000] {taskinstance.py:3280} INFO - 0 downstream tasks scheduled from follow-on schedule check
