[2025-05-18T20:03:03.249+0000] {taskinstance.py:1956} INFO - Dependencies all met for dep_context=non-requeueable deps ti=<TaskInstance: telegram_summary_channel_1137503644.summarize_daily_posts manual__2025-05-18T19:59:52.758922+00:00 [queued]>
[2025-05-18T20:03:03.264+0000] {taskinstance.py:1956} INFO - Dependencies all met for dep_context=requeueable deps ti=<TaskInstance: telegram_summary_channel_1137503644.summarize_daily_posts manual__2025-05-18T19:59:52.758922+00:00 [queued]>
[2025-05-18T20:03:03.265+0000] {taskinstance.py:2170} INFO - Starting attempt 1 of 2
[2025-05-18T20:03:03.289+0000] {taskinstance.py:2191} INFO - Executing <Task(DockerOperator): summarize_daily_posts> on 2025-05-18 19:59:52.758922+00:00
[2025-05-18T20:03:03.299+0000] {standard_task_runner.py:60} INFO - Started process 327 to run task
[2025-05-18T20:03:03.306+0000] {standard_task_runner.py:87} INFO - Running: ['airflow', 'tasks', 'run', 'telegram_summary_channel_1137503644', 'summarize_daily_posts', 'manual__2025-05-18T19:59:52.758922+00:00', '--job-id', '52', '--raw', '--subdir', 'DAGS_FOLDER/dag_generator.py', '--cfg-path', '/tmp/tmp1e_arzmx']
[2025-05-18T20:03:03.310+0000] {standard_task_runner.py:88} INFO - Job 52: Subtask summarize_daily_posts
[2025-05-18T20:03:03.406+0000] {task_command.py:423} INFO - Running <TaskInstance: telegram_summary_channel_1137503644.summarize_daily_posts manual__2025-05-18T19:59:52.758922+00:00 [running]> on host a891a85dd282
[2025-05-18T20:03:03.585+0000] {taskinstance.py:2480} INFO - Exporting env vars: AIRFLOW_CTX_DAG_OWNER='airflow' AIRFLOW_CTX_DAG_ID='telegram_summary_channel_1137503644' AIRFLOW_CTX_TASK_ID='summarize_daily_posts' AIRFLOW_CTX_EXECUTION_DATE='2025-05-18T19:59:52.758922+00:00' AIRFLOW_CTX_TRY_NUMBER='1' AIRFLOW_CTX_DAG_RUN_ID='manual__2025-05-18T19:59:52.758922+00:00'
[2025-05-18T20:03:03.667+0000] {docker.py:359} INFO - Starting docker container from image telegram_summarizer_task:latest
[2025-05-18T20:03:04.543+0000] {docker.py:429} INFO - [2025-05-18 20:03:04] [INFO] [Summarizer] - Запуск основного процесса суммризатора (локальный или прямой вызов)...
[2025-05-18 20:03:04] [INFO] [Summarizer] - --- Запуск скрипта суммризации (Airflow Task) ---
[2025-05-18 20:03:04] [INFO] [Summarizer] - Попытка разбора XCom из переменной окружения 'XCOM_DATA_JSON'...
[2025-05-18T20:03:04.546+0000] {docker.py:429} INFO - [2025-05-18 20:03:04] [ERROR] [Summarizer] - Ошибка: Не удалось прочитать или распарсить данные из 'XCOM_DATA_JSON': Expecting ',' delimiter: line 1 column 6 (char 5)
Traceback (most recent call last):
  File "/app/summarizer.py", line 267, in main
    xcom_data = json.loads(xcom_data_json_str)
  File "/usr/local/lib/python3.9/json/__init__.py", line 346, in loads
    return _default_decoder.decode(s)
  File "/usr/local/lib/python3.9/json/decoder.py", line 337, in decode
    obj, end = self.raw_decode(s, idx=_w(s, 0).end())
  File "/usr/local/lib/python3.9/json/decoder.py", line 353, in raw_decode
    obj, end = self.scan_once(s, idx)
json.decoder.JSONDecodeError: Expecting ',' delimiter: line 1 column 6 (char 5)
[2025-05-18 20:03:04] [ERROR] [Summarizer] - Содержимое переменной 'XCOM_DATA_JSON': [2025-05-18 20:03:01] [INFO] [Parser] - Перехвачен SystemExit с кодом 0. Завершение.
[2025-05-18 20:03:01] [INFO] [Parser] - Скрипт парсера окончательно завершается с кодом 0 (из __main__ блока).
[2025-05-18T20:03:04.546+0000] {docker.py:429} INFO - [2025-05-18 20:03:04] [WARNING] [Summarizer] - Скрипт суммризации завершается через sys.exit() с кодом: 1
[2025-05-18 20:03:04] [INFO] [Summarizer] - --- Скрипт суммризации завершен с кодом выхода: 1 ---
[2025-05-18 20:03:04] [INFO] [Summarizer] - Суммризатор: Перехвачен SystemExit с кодом 1. Завершение.
[2025-05-18 20:03:04] [INFO] [Summarizer] - Скрипт суммризатора окончательно завершается с кодом 1 (из __main__ блока).
[2025-05-18T20:03:04.841+0000] {taskinstance.py:2698} ERROR - Task failed with exception
Traceback (most recent call last):
  File "/home/airflow/.local/lib/python3.8/site-packages/airflow/models/taskinstance.py", line 433, in _execute_task
    result = execute_callable(context=context, **execute_callable_kwargs)
  File "/home/airflow/.local/lib/python3.8/site-packages/airflow/providers/docker/operators/docker.py", line 502, in execute
    return self._run_image()
  File "/home/airflow/.local/lib/python3.8/site-packages/airflow/providers/docker/operators/docker.py", line 376, in _run_image
    return self._run_image_with_mounts(self.mounts, add_tmp_variable=False)
  File "/home/airflow/.local/lib/python3.8/site-packages/airflow/providers/docker/operators/docker.py", line 437, in _run_image_with_mounts
    raise DockerContainerFailedException(f"Docker container failed: {result!r}", logs=log_lines)
airflow.providers.docker.exceptions.DockerContainerFailedException: Docker container failed: {'StatusCode': 1}
[2025-05-18T20:03:04.844+0000] {taskinstance.py:1138} INFO - Marking task as UP_FOR_RETRY. dag_id=telegram_summary_channel_1137503644, task_id=summarize_daily_posts, execution_date=20250518T195952, start_date=20250518T200303, end_date=20250518T200304
[2025-05-18T20:03:04.865+0000] {standard_task_runner.py:107} ERROR - Failed to execute job 52 for task summarize_daily_posts (Docker container failed: {'StatusCode': 1}; 327)
[2025-05-18T20:03:04.893+0000] {local_task_job_runner.py:234} INFO - Task exited with return code 1
[2025-05-18T20:03:04.912+0000] {taskinstance.py:3280} INFO - 0 downstream tasks scheduled from follow-on schedule check
