[2025-05-16T21:00:00.790+0000] {taskinstance.py:1956} INFO - Dependencies all met for dep_context=non-requeueable deps ti=<TaskInstance: telegram_summary_channel_1137503644.parse_channel_posts scheduled__2025-05-16T20:30:00+00:00 [queued]>
[2025-05-16T21:00:00.806+0000] {taskinstance.py:1956} INFO - Dependencies all met for dep_context=requeueable deps ti=<TaskInstance: telegram_summary_channel_1137503644.parse_channel_posts scheduled__2025-05-16T20:30:00+00:00 [queued]>
[2025-05-16T21:00:00.807+0000] {taskinstance.py:2170} INFO - Starting attempt 1 of 2
[2025-05-16T21:00:00.834+0000] {taskinstance.py:2191} INFO - Executing <Task(DockerOperator): parse_channel_posts> on 2025-05-16 20:30:00+00:00
[2025-05-16T21:00:00.845+0000] {standard_task_runner.py:60} INFO - Started process 178 to run task
[2025-05-16T21:00:00.850+0000] {standard_task_runner.py:87} INFO - Running: ['airflow', 'tasks', 'run', 'telegram_summary_channel_1137503644', 'parse_channel_posts', 'scheduled__2025-05-16T20:30:00+00:00', '--job-id', '12', '--raw', '--subdir', 'DAGS_FOLDER/dag_generator.py', '--cfg-path', '/tmp/tmptk6x0d3n']
[2025-05-16T21:00:00.853+0000] {standard_task_runner.py:88} INFO - Job 12: Subtask parse_channel_posts
[2025-05-16T21:00:00.926+0000] {task_command.py:423} INFO - Running <TaskInstance: telegram_summary_channel_1137503644.parse_channel_posts scheduled__2025-05-16T20:30:00+00:00 [running]> on host 0bcec1437f05
[2025-05-16T21:00:01.015+0000] {taskinstance.py:2480} INFO - Exporting env vars: AIRFLOW_CTX_DAG_OWNER='airflow' AIRFLOW_CTX_DAG_ID='telegram_summary_channel_1137503644' AIRFLOW_CTX_TASK_ID='parse_channel_posts' AIRFLOW_CTX_EXECUTION_DATE='2025-05-16T20:30:00+00:00' AIRFLOW_CTX_TRY_NUMBER='1' AIRFLOW_CTX_DAG_RUN_ID='scheduled__2025-05-16T20:30:00+00:00'
[2025-05-16T21:00:01.092+0000] {docker.py:359} INFO - Starting docker container from image telegram_parser_task:latest
[2025-05-16T21:00:01.742+0000] {docker.py:429} INFO - [2025-05-16 21:00:01] [INFO] [Parser] - Запуск основного асинхронного процесса парсера (локальный или прямой вызов)...
[2025-05-16T21:00:01.744+0000] {docker.py:429} INFO - [2025-05-16 21:00:01] [INFO] [Parser] - --- Запуск скрипта парсера (Airflow Task) ---
[2025-05-16 21:00:01] [INFO] [Parser] - Целевой канал (идентификатор для Telethon): https://t.me/trader_chernyh
[2025-05-16 21:00:01] [INFO] [Parser] - Числовой ID канала (из конфига DAG): 1137503644
[2025-05-16 21:00:01] [INFO] [Parser] - Целевая дата парсинга: 2025-05-16
[2025-05-16 21:00:01] [INFO] [Parser] - Попытка подключения к БД (1/5): host=postgres_results_db_service port=5432 dbname=parsing_results user=parser_user
[2025-05-16T21:00:01.762+0000] {docker.py:429} INFO - [2025-05-16 21:00:01] [INFO] [Parser] - Успешное подключение к БД!
[2025-05-16 21:00:01] [INFO] [Parser] - Проверка/создание таблицы 'telegram_messages'...
[2025-05-16T21:00:01.785+0000] {docker.py:429} INFO - [2025-05-16 21:00:01] [INFO] [Parser] - Схема БД 'telegram_messages' проверена/обновлена.
[2025-05-16 21:00:01] [INFO] [Parser] - Инициализация Telegram клиента с сессией: /app/session/session/my_telegram_session
[2025-05-16 21:00:01] [INFO] [Parser] - Файл сессии '/app/session/session/my_telegram_session.session' существует: False
[2025-05-16T21:00:01.792+0000] {docker.py:429} INFO - [2025-05-16 21:00:01] [ERROR] [Parser] - Непредвиденная ошибка при инициализации Telegram клиента: unable to open database file
Traceback (most recent call last):
  File "/app/telegram_parser.py", line 211, in initialize_telegram_client
    telegram_client = TelegramClient(TELEGRAM_SESSION_PATH, int(TELEGRAM_API_ID), TELEGRAM_API_HASH)
  File "/usr/local/lib/python3.9/site-packages/telethon/client/telegrambaseclient.py", line 290, in __init__
    session = SQLiteSession(str(session))
  File "/usr/local/lib/python3.9/site-packages/telethon/sessions/sqlite.py", line 47, in __init__
    c = self._cursor()
  File "/usr/local/lib/python3.9/site-packages/telethon/sessions/sqlite.py", line 242, in _cursor
    self._conn = sqlite3.connect(self.filename,
sqlite3.OperationalError: unable to open database file
[2025-05-16 21:00:01] [ERROR] [Parser] - Критическая ошибка в main: Не удалось инициализировать или подключиться к Telegram.
Traceback (most recent call last):
  File "/app/telegram_parser.py", line 452, in main
    raise Exception("Не удалось инициализировать или подключиться к Telegram.")
Exception: Не удалось инициализировать или подключиться к Telegram.
[2025-05-16 21:00:01] [INFO] [Parser] - Запись данных XCom в файл: /airflow/xcom/return.json
[2025-05-16T21:00:01.793+0000] {docker.py:429} INFO - [2025-05-16 21:00:01] [INFO] [Parser] - Создана директория для XCom: /airflow/xcom
[2025-05-16 21:00:01] [INFO] [Parser] - Данные XCom успешно записаны: {'channel_id': 1137503644, 'target_date_str': '2025-05-16', 'status': 'failure', 'error_type': 'Exception', 'error_message': 'Не удалось инициализировать или подключиться к Telegram.'}
[2025-05-16 21:00:01] [INFO] [Parser] - Закрытие соединения с БД...
[2025-05-16T21:00:01.793+0000] {docker.py:429} INFO - [2025-05-16 21:00:01] [INFO] [Parser] - Соединение с БД закрыто.
[2025-05-16 21:00:01] [INFO] [Parser] - --- Скрипт парсера завершен с кодом выхода: 1 ---
[2025-05-16T21:00:01.794+0000] {docker.py:429} INFO - [2025-05-16 21:00:01] [INFO] [Parser] - Перехвачен SystemExit с кодом 1. Завершение.
[2025-05-16T21:00:01.794+0000] {docker.py:429} INFO - [2025-05-16 21:00:01] [INFO] [Parser] - Скрипт парсера окончательно завершается с кодом 1 (из __main__ блока).
[2025-05-16T21:00:02.227+0000] {taskinstance.py:2698} ERROR - Task failed with exception
Traceback (most recent call last):
  File "/home/airflow/.local/lib/python3.8/site-packages/airflow/models/taskinstance.py", line 433, in _execute_task
    result = execute_callable(context=context, **execute_callable_kwargs)
  File "/home/airflow/.local/lib/python3.8/site-packages/airflow/providers/docker/operators/docker.py", line 502, in execute
    return self._run_image()
  File "/home/airflow/.local/lib/python3.8/site-packages/airflow/providers/docker/operators/docker.py", line 376, in _run_image
    return self._run_image_with_mounts(self.mounts, add_tmp_variable=False)
  File "/home/airflow/.local/lib/python3.8/site-packages/airflow/providers/docker/operators/docker.py", line 437, in _run_image_with_mounts
    raise DockerContainerFailedException(f"Docker container failed: {result!r}", logs=log_lines)
airflow.providers.docker.exceptions.DockerContainerFailedException: Docker container failed: {'StatusCode': 1}
[2025-05-16T21:00:02.230+0000] {taskinstance.py:1138} INFO - Marking task as UP_FOR_RETRY. dag_id=telegram_summary_channel_1137503644, task_id=parse_channel_posts, execution_date=20250516T203000, start_date=20250516T210000, end_date=20250516T210002
[2025-05-16T21:00:02.251+0000] {standard_task_runner.py:107} ERROR - Failed to execute job 12 for task parse_channel_posts (Docker container failed: {'StatusCode': 1}; 178)
[2025-05-16T21:00:02.272+0000] {local_task_job_runner.py:234} INFO - Task exited with return code 1
[2025-05-16T21:00:02.321+0000] {taskinstance.py:3280} INFO - 0 downstream tasks scheduled from follow-on schedule check
